[2023-11-01T20:54:31.483-0700] {taskinstance.py:1083} INFO - Dependencies all met for <TaskInstance: dbt_snowflake_dag.bookings_2_seed manual__2023-11-02T03:54:15.929995+00:00 [queued]>
[2023-11-01T20:54:31.488-0700] {taskinstance.py:1083} INFO - Dependencies all met for <TaskInstance: dbt_snowflake_dag.bookings_2_seed manual__2023-11-02T03:54:15.929995+00:00 [queued]>
[2023-11-01T20:54:31.488-0700] {taskinstance.py:1279} INFO - 
--------------------------------------------------------------------------------
[2023-11-01T20:54:31.488-0700] {taskinstance.py:1280} INFO - Starting attempt 1 of 1
[2023-11-01T20:54:31.488-0700] {taskinstance.py:1281} INFO - 
--------------------------------------------------------------------------------
[2023-11-01T20:54:31.492-0700] {taskinstance.py:1300} INFO - Executing <Task(DbtSeedLocalOperator): bookings_2_seed> on 2023-11-02 03:54:15.929995+00:00
[2023-11-01T20:54:31.494-0700] {standard_task_runner.py:55} INFO - Started process 3369 to run task
[2023-11-01T20:54:31.496-0700] {standard_task_runner.py:82} INFO - Running: ['airflow', 'tasks', 'run', 'dbt_snowflake_dag', 'bookings_2_seed', 'manual__2023-11-02T03:54:15.929995+00:00', '--job-id', '83', '--raw', '--subdir', 'DAGS_FOLDER/dbt_airflow_snowflake.py', '--cfg-path', '/var/folders/jh/g6c8fm7j3x148qd22mrgmrsw0000gn/T/tmp2al687c4']
[2023-11-01T20:54:31.497-0700] {standard_task_runner.py:83} INFO - Job 83: Subtask bookings_2_seed
[2023-11-01T20:54:31.514-0700] {task_command.py:388} INFO - Running <TaskInstance: dbt_snowflake_dag.bookings_2_seed manual__2023-11-02T03:54:15.929995+00:00 [running]> on host anishs-air.lan
[2023-11-01T20:54:31.531-0700] {taskinstance.py:1507} INFO - Exporting the following env vars:
AIRFLOW_CTX_DAG_OWNER=airflow
AIRFLOW_CTX_DAG_ID=dbt_snowflake_dag
AIRFLOW_CTX_TASK_ID=bookings_2_seed
AIRFLOW_CTX_EXECUTION_DATE=2023-11-02T03:54:15.929995+00:00
AIRFLOW_CTX_TRY_NUMBER=1
AIRFLOW_CTX_DAG_RUN_ID=manual__2023-11-02T03:54:15.929995+00:00
[2023-11-01T20:54:31.531-0700] {local.py:194} INFO - Cloning project to writable temp directory /var/folders/jh/g6c8fm7j3x148qd22mrgmrsw0000gn/T/tmpohk9mcbt from /Users/anishmore/airflow/dbt/data_pipeline
[2023-11-01T20:54:31.583-0700] {subprocess.py:60} INFO - Tmp dir root location: 
 /var/folders/jh/g6c8fm7j3x148qd22mrgmrsw0000gn/T
[2023-11-01T20:54:31.584-0700] {subprocess.py:73} INFO - Running command: ['/opt/homebrew/bin/dbt', 'deps']
[2023-11-01T20:54:31.588-0700] {subprocess.py:84} INFO - Command output:
[2023-11-01T20:54:32.650-0700] {subprocess.py:94} INFO - [0m03:54:32  Running with dbt=1.6.7
[2023-11-01T20:54:32.930-0700] {subprocess.py:94} INFO - [0m03:54:32  Installing dbt-labs/dbt_utils
[2023-11-01T20:54:33.431-0700] {subprocess.py:94} INFO - [0m03:54:33  Installed from version 1.1.1
[2023-11-01T20:54:33.432-0700] {subprocess.py:94} INFO - [0m03:54:33  Up to date!
[2023-11-01T20:54:33.961-0700] {subprocess.py:98} INFO - Command exited with return code 0
[2023-11-01T20:54:33.966-0700] {base.py:73} INFO - Using connection ID 'snowflake_conn' for task execution.
[2023-11-01T20:54:33.967-0700] {crypto.py:83} WARNING - empty cryptography key - values will not be stored encrypted.
[2023-11-01T20:54:33.968-0700] {base.py:147} INFO - Using real values for profile default
[2023-11-01T20:54:33.980-0700] {taskinstance.py:1768} ERROR - Task failed with exception
Traceback (most recent call last):
  File "/opt/homebrew/lib/python3.10/site-packages/cosmos/operators/local.py", line 412, in execute
    self.build_and_run_cmd(context=context, cmd_flags=cmd_flags)
  File "/opt/homebrew/lib/python3.10/site-packages/cosmos/operators/local.py", line 361, in build_and_run_cmd
    result = self.run_command(cmd=dbt_cmd, env=env, context=context)
  File "/opt/homebrew/lib/python3.10/site-packages/cosmos/operators/local.py", line 215, in run_command
    with self.profile_config.ensure_profile() as (profile_path, env_vars):
  File "/opt/homebrew/Cellar/python@3.10/3.10.12_1/Frameworks/Python.framework/Versions/3.10/lib/python3.10/contextlib.py", line 135, in __enter__
    return next(self.gen)
  File "/opt/homebrew/lib/python3.10/site-packages/cosmos/config.py", line 183, in ensure_profile
    env_vars = self.profile_mapping.env_vars
  File "/opt/homebrew/lib/python3.10/site-packages/cosmos/profiles/base.py", line 130, in env_vars
    raise CosmosValueError(f"Could not find a value for secret field {field}.")
cosmos.exceptions.CosmosValueError: Could not find a value for secret field private_key.
[2023-11-01T20:54:33.986-0700] {taskinstance.py:1318} INFO - Marking task as FAILED. dag_id=dbt_snowflake_dag, task_id=bookings_2_seed, execution_date=20231102T035415, start_date=20231102T035431, end_date=20231102T035433
[2023-11-01T20:54:33.992-0700] {standard_task_runner.py:100} ERROR - Failed to execute job 83 for task bookings_2_seed (Could not find a value for secret field private_key.; 3369)
[2023-11-01T20:54:34.009-0700] {local_task_job.py:208} INFO - Task exited with return code 1
[2023-11-01T20:54:34.017-0700] {taskinstance.py:2578} INFO - 0 downstream tasks scheduled from follow-on schedule check
